[1034416   14160]
EPOCH BATCH VALIDATION ERROR................................................COST
0     5510     43.456736%.............................................[0.014900]
1     5510     43.459640%.............................................[0.014872]
2     5510     43.443670%.............................................[0.014902]
3     5510     43.433508%.............................................[0.014898]
4     5510     43.424797%.............................................[0.014902]
5     5510     43.411731%.............................................[0.014905]
6     5510     43.381243%.............................................[0.014926]
7     5510     43.366725%.............................................[0.014916]
8     5510     43.349303%.............................................[0.014918]
9     5510     43.350755%.............................................[0.014947]
10     5510     43.326074%............................................[0.014929]
11     5510     43.305749%............................................[0.014929]
12     5510     43.275261%............................................[0.014931]
13     5510     43.265099%............................................[0.014934]
14     5510     43.233159%............................................[0.014940]
15     5510     43.256388%............................................[0.014853]
16     5510     43.236063%............................................[0.014912]
17     5510     43.225900%............................................[0.014937]
18     5510     43.220093%............................................[0.014928]
19     5510     43.207027%............................................[0.014913]
saving model to ../../data/models/best_default_model_mlp.pkl....................
The code ran for...............................................57.991789 seconds
(1024, 1024) (1102, 1102)
starting prediction.............................................................
loading best model..........................................................done
test set dim [1048576    1521]
starting training...............................................................
mlptrainingmodule loading data...
<<!! BUG IN FGRAPH.REPLACE OR A LISTENER !!>> <class 'theano.gof.fg.CachedConstantError'> You manually constructed a FunctionGraph, but you passed it a graph that has a cached constant. This should not happen. Clone the graph before building the FunctionGraph. local_upcast_elemwise_constant_inputs
ERROR (theano.gof.opt): Optimization failure due to: local_upcast_elemwise_constant_inputs
ERROR (theano.gof.opt): TRACEBACK:
---predicted values---
[0 0 0 ..., 0 0 0]
ERROR (theano.gof.opt): Traceback (most recent call last):
  File "/home/fgonda/iconenv/local/lib/python2.7/site-packages/theano/gof/opt.py", line 1527, in process_node
    fgraph.replace_all_validate(repl_pairs, reason=lopt)
  File "/home/fgonda/iconenv/local/lib/python2.7/site-packages/theano/gof/toolbox.py", line 259, in replace_all_validate
    fgraph.replace(r, new_r, reason=reason, verbose=False)
  File "/home/fgonda/iconenv/local/lib/python2.7/site-packages/theano/gof/fg.py", line 502, in replace
    self.change_input(node, i, new_r, reason=reason)
  File "/home/fgonda/iconenv/local/lib/python2.7/site-packages/theano/gof/fg.py", line 442, in change_input
    self.__import_r__([new_r], reason=reason)
  File "/home/fgonda/iconenv/local/lib/python2.7/site-packages/theano/gof/fg.py", line 257, in __import_r__
    self.__import__(apply_node, reason=reason)
  File "/home/fgonda/iconenv/local/lib/python2.7/site-packages/theano/gof/fg.py", line 373, in __import__
    self.__setup_r__(input)
  File "/home/fgonda/iconenv/local/lib/python2.7/site-packages/theano/gof/fg.py", line 148, in __setup_r__
    "You manually constructed a FunctionGraph, but you passed it a"
CachedConstantError: You manually constructed a FunctionGraph, but you passed it a graph that has a cached constant. This should not happen. Clone the graph before building the FunctionGraph.

<<!! BUG IN FGRAPH.REPLACE OR A LISTENER !!>> <type 'exceptions.AssertionError'>  local_mul_canonizer
ERROR (theano.gof.opt): Optimization failure due to: local_mul_canonizer
ERROR (theano.gof.opt): TRACEBACK:
ERROR (theano.gof.opt): Traceback (most recent call last):
  File "/home/fgonda/iconenv/local/lib/python2.7/site-packages/theano/gof/opt.py", line 1527, in process_node
    fgraph.replace_all_validate(repl_pairs, reason=lopt)
  File "/home/fgonda/iconenv/local/lib/python2.7/site-packages/theano/gof/toolbox.py", line 259, in replace_all_validate
    fgraph.replace(r, new_r, reason=reason, verbose=False)
  File "/home/fgonda/iconenv/local/lib/python2.7/site-packages/theano/gof/fg.py", line 501, in replace
    assert (node == 'output' and self.outputs[i] is r) or (node.inputs[i] is r)
AssertionError

Exception in thread training:
Traceback (most recent call last):
  File "/usr/lib/python2.7/threading.py", line 810, in __bootstrap_inner
    self.run()
  File "/home/fgonda/icon/code/model/tasks.py", line 65, in run
    self.work()
  File "/home/fgonda/icon/code/model/tasks.py", line 193, in work
    self.classifier.train()
  File "/home/fgonda/icon/code/model/mlp_classifier.py", line 143, in train
    (self.index + 1) * test_batch_size]})
  File "/home/fgonda/iconenv/local/lib/python2.7/site-packages/theano/compile/function.py", line 266, in function
    profile=profile)
  File "/home/fgonda/iconenv/local/lib/python2.7/site-packages/theano/compile/pfunc.py", line 511, in pfunc
    on_unused_input=on_unused_input)
  File "/home/fgonda/iconenv/local/lib/python2.7/site-packages/theano/compile/function_module.py", line 1465, in orig_function
    on_unused_input=on_unused_input).create(
  File "/home/fgonda/iconenv/local/lib/python2.7/site-packages/theano/compile/function_module.py", line 1160, in __init__
    optimizer_profile = optimizer(fgraph)
  File "/home/fgonda/iconenv/local/lib/python2.7/site-packages/theano/gof/opt.py", line 90, in __call__
    return self.optimize(fgraph)
  File "/home/fgonda/iconenv/local/lib/python2.7/site-packages/theano/gof/opt.py", line 81, in optimize
    ret = self.apply(fgraph, *args, **kwargs)
  File "/home/fgonda/iconenv/local/lib/python2.7/site-packages/theano/gof/opt.py", line 195, in apply
    sub_prof = optimizer.optimize(fgraph)
  File "/home/fgonda/iconenv/local/lib/python2.7/site-packages/theano/gof/opt.py", line 81, in optimize
    ret = self.apply(fgraph, *args, **kwargs)
  File "/home/fgonda/iconenv/local/lib/python2.7/site-packages/theano/gof/opt.py", line 1837, in apply
    lopt_change = self.process_node(fgraph, node, lopt)
  File "/home/fgonda/iconenv/local/lib/python2.7/site-packages/theano/gof/opt.py", line 1535, in process_node
    self.failure_callback(e, self, repl_pairs, lopt)
  File "/home/fgonda/iconenv/local/lib/python2.7/site-packages/theano/gof/opt.py", line 1396, in warn_inplace
    return NavigatorOptimizer.warn(exc, nav, repl_pairs, local_opt)
  File "/home/fgonda/iconenv/local/lib/python2.7/site-packages/theano/gof/opt.py", line 1386, in warn
    raise exc
AssertionError

[0 1]
[1033094   15482]
^Cshutting down....................................icon (interactive connectomics)
stopping...........................................................training task
stopping.........................................................prediction task
shutdown....................................................................done
(iconenv)fgonda@gpu1:~/icon/code/model$ test set dim [1048576    1521]
-bash: test: too many arguments
(iconenv)fgonda@gpu1:~/icon/code/model
